Workbook

Sheet P1 Lunch
A1: Problem 1 | School lunch planning
A2: Mahir Nagersheth | mnagersh | HW2 | Canvas uploader: mnagersh
A4: Input / variable | B4: Dish 1 | C4: Dish 2 | D4: Dish 3
A5: Unit cost | B5: 4 | C5: 1 | D5: 3
A6: Cooking minutes | B6: 3 | C6: 2 | D6: 2
A7: Shelf space | B7: 0.1 | C7: 0.2 | D7: 0.15
A8: Minimum meals | B8: 10 | C8: 10 | D8: 10
A10: Meals to prepare | B10: 35 | C10: 15 | D10: 10
A12: Total cost | B12: =SUMPRODUCT(B5:D5,B10:D10) -> 185
A14: Constraint | B14: Used / LHS | C14: Relation | D14: Limit / RHS | E14: Slack
A15: Cooking time | B15: =SUMPRODUCT(B6:D6,B10:D10) -> 155 | C15: <= | D15: 180 | E15: =D15-B15 -> 25
A16: Shelf storage | B16: =SUMPRODUCT(B7:D7,B10:D10) -> 8 | C16: <= | D16: 8 | E16: =D16-B16 -> 0
A17: Total demand | B17: =SUM(B10:D10) -> 60 | C17: >= | D17: 60 | E17: =B17-D17 -> 0
A18: Minimum Dish 1 | B18: =B10 -> 35 | C18: >= | D18: =B8 -> 10 | E18: =B18-D18 -> 25
A19: Minimum Dish 2 | B19: =C10 -> 15 | C19: >= | D19: =C8 -> 10 | E19: =B19-D19 -> 5
A20: Minimum Dish 3 | B20: =D10 -> 10 | C20: >= | D20: =D8 -> 10 | E20: =B20-D20 -> 0
A23: Solver setting | B23: Specification
A24: Objective: $B$12, Min. Changing cells: $B$10:$D$10.
A25: Constraints: $B$15:$B$16 <= $D$15:$D$16; $B$17:$B$20 >= $D$17:$D$20.
A26: Method: Simplex LP. Make unconstrained variables non-negative. No integer constraints; request Sensitivity report after Solve.
A28: Formula cell(s) | B28: Formula / explanation
A29: B12 | B29: =SUMPRODUCT(B5:D5,B10:D10)
A30: B15 | B30: =SUMPRODUCT(B6:D6,B10:D10)
A31: E15 | B31: =D15-B15
A32: B16 | B32: =SUMPRODUCT(B7:D7,B10:D10)
A33: E16 | B33: =D16-B16
A34: B17 | B34: =SUM(B10:D10)
A35: E17 | B35: =B17-D17
A36: B18 | B36: =B10
A37: D18 | B37: =B8
A38: E18 | B38: =B18-D18
A39: B19 | B39: =C10
... A44: E20 | B44: =B20-D20

Sheet P1 Sensitivity
A1: Problem 1 | Analytical sensitivity check
A4: Analytically reconstructed sensitivity values, checked against the LP basis. The native Excel report, if generated, is an additional worksheet. Ranges vary one input at a time.
A6: Variable | B6: Final value | C6: Reduced cost* | D6: Cost coefficient | E6: Allow. increase | F6: Allow. decrease
A7: Dish 1 | B7: 35 | C7: 0 | D7: 4 | E7: 1 | F7: 3
A8: Dish 2 | B8: 15 | C8: 0 | D8: 1 | E8: 1 | F8: Infinity
A9: Dish 3 | B9: 10 | C9: 0.5 | D9: 3 | E9: Infinity | F9: 0.5
A10: *When the Dish 3 minimum is treated as a variable bound, its reduced cost is 0.5. With an explicit minimum row, the same marginal can be reported as that row's shadow price.
A12: Constraint | B12: Final LHS | C12: Shadow price | D12: RHS | E12: Allow. increase | F12: Allow. decrease
A13: Time | B13: 155 | C13: 0 | D13: 180 | E13: Infinity | F13: 25
A14: Storage | B14: 8 | C14: -30 | D14: 8 | E14: 2.5 | F14: 0.5
A15: Demand | B15: 60 | C15: 7 | D15: 60 | E15: 5 | F15: 12.5
A16: Dish 1 minimum | B16: 35 | C16: 0 | D16: 10 | E16: 25 | F16: Infinity
A17: Dish 2 minimum | B17: 15 | C17: 0 | D17: 10 | E17: 5 | F17: Infinity
A18: Dish 3 minimum | B18: 10 | C18: 0.5 | D18: 10 | E18: 10 | F18: 10
A21: Binding: storage, demand, and Dish 3 minimum. A binding constraint holds with equality at the optimum. Time has 25 minutes of slack; Dish 1 and Dish 2 minima have slack 25 and 5.
A23: Storage: one additional shelf lowers minimum cost by $30 for RHS in [7.5,10.5]. Demand: one additional required meal raises minimum cost by $7 for RHS in [47.5,65].
A25: Dish 3 minimum: one additional required Dish 3 meal raises minimum cost by $0.50 for its RHS in [0,20]. Other parameters stay fixed in each interpretation.

Sheet P1 Demand
A1: Problem 1(f) | Cost versus required lunches
A4: Breakpoint | B4: Value | C4: Explanation
A5: Minimum production | B5: =SUM('P1 Lunch'!B8:D8) -> 30
A6: Storage kink | B6: =('P1 Lunch'!D16-'P1 Lunch'!B7*'P1 Lunch'!B8-'P1 Lunch'!D7*'P1 Lunch'!D8)/'P1 Lunch'!C7+'P1 Lunch'!B8+'P1 Lunch'!D8 -> 47.5
A7: Maximum lunches | B7: =('P1 Lunch'!D16-('P1 Lunch'!C7-'P1 Lunch'!B7)*'P1 Lunch'!C8-('P1 Lunch'!D7-'P1 Lunch'!B7)*'P1 Lunch'!D8)/'P1 Lunch'!B7 -> 65
A9: Continuous LP curve for the stated parameters: cost = 80 for D <= 30; D + 50 for 30 <= D <= 47.5; 7D - 235 for 47.5 <= D <= 65. D > 65 is infeasible.
A10: Chart formulas encode the stated basis regimes. If capacities or costs change, re-solve the LP before using these regimes. At D=65: (45,10,10), cost $220, cooking time 175.
A12: Required lunches | B12: Dish 1 | C12: Dish 2 | D12: Dish 3 | E12: Minimum cost | F12: Cooking minutes | G12: Shelves used | H12: Status
A13: 0 | B13: =IF(A13>$B$7,"",IF(A13<=$B$6,10,2*A13-85)) -> 10 | C13: =IF(A13>$B$7,"",IF(A13<=$B$5,10,IF(A13<=$B$6,A13-20,75-A13))) -> 10 | D13: =IF(A13>$B$7,"",10) -> 10 | E13: =IF(A13>$B$7,"",SUMPRODUCT(B13:D13,'P1 Lunch'!$B$5:$D$5)) -> 80 | F13: =IF(A13>$B$7,"",SUMPRODUCT(B13:D13,'P1 Lunch'!$B$6:$D$6)) -> 70 | G13: =IF(A13>$B$7,"",SUMPRODUCT(B13:D13,'P1 Lunch'!$B$7:$D$7)) -> 4.5 | H13: =IF(A13>$B$7,"Infeasible","Feasible") -> Feasible
A14: 0.5 | B14: =IF(A14>$B$7,"",IF(A14<=$B$6,10,2*A14-85)) -> 10 | C14: =IF(A14>$B$7,"",IF(A14<=$B$5,10,IF(A14<=$B$6,A14-20,75-A14))) -> 10 | D14: =IF(A14>$B$7,"",10) -> 10 | E14: =IF(A14>$B$7,"",SUMPRODUCT(B14:D14,'P1 Lunch'!$B$5:$D$5)) -> 80 | F14: =IF(A14>$B$7,"",SUMPRODUCT(B14:D14,'P1 Lunch'!$B$6:$D$6)) -> 70 | G14: =IF(A14>$B$7,"",SUMPRODUCT(B14:D14,'P1 Lunch'!$B$7:$D$7)) -> 4.5 | H14: =IF(A14>$B$7,"Infeasible","Feasible") -> Feasible
A15: 1 | B15: =IF(A15>$B$7,"",IF(A15<=$B$6,10,2*A15-85)) -> 10 | C15: =IF(A15>$B$7,"",IF(A15<=$B$5,10,IF(A15<=$B$6,A15-20,75-A15))) -> 10 | D15: =IF(A15>$B$7,"",10) -> 10 | E15: =IF(A15>$B$7,"",SUMPRODUCT(B15:D15,'P1 Lunch'!$B$5:$D$5)) -> 80 | F15: =IF(A15>$B$7,"",SUMPRODUCT(B15:D15,'P1 Lunch'!$B$6:$D$6)) -> 70 | G15: =IF(A15>$B$7,"",SUMPRODUCT(B15:D15,'P1 Lunch'!$B$7:$D$7)) -> 4.5 | H15: =IF(A15>$B$7,"Infeasible","Feasible") -> Feasible
A16: 1.5 | B16: =IF(A16>$B$7,"",IF(A16<=$B$6,10,2*A16-85)) -> 10 | C16: =IF(A16>$B$7,"",IF(A16<=$B$5,10,IF(A16<=$B$6,A16-20,75-A16))) -> 10 | D16: =IF(A16>$B$7,"",10) -> 10 | E16: =IF(A16>$B$7,"",SUMPRODUCT(B16:D16,'P1 Lunch'!$B$5:$D$5)) -> 80 | F16: =IF(A16>$B$7,"",SUMPRODUCT(B16:D16,'P1 Lunch'!$B$6:$D$6)) -> 70 | G16: =IF(A16>$B$7,"",SUMPRODUCT(B16:D16,'P1 Lunch'!$B$7:$D$7)) -> 4.5 | H16: =IF(A16>$B$7,"Infeasible","Feasible") -> Feasible
A17: 2 | B17: =IF(A17>$B$7,"",IF(A17<=$B$6,10,2*A17-85)) -> 10 | C17: =IF(A17>$B$7,"",IF(A17<=$B$5,10,IF(A17<=$B$6,A17-20,75-A17))) -> 10 | D17: =IF(A17>$B$7,"",10) -> 10 | E17: =IF(A17>$B$7,"",SUMPRODUCT(B17:D17,'P1 Lunch'!$B$5:$D$5)) -> 80 | F17: =IF(A17>$B$7,"",SUMPRODUCT(B17:D17,'P1 Lunch'!$B$6:$D$6)) -> 70 | G17: =IF(A17>$B$7,"",SUMPRODUCT(B17:D17,'P1 Lunch'!$B$7:$D$7)) -> 4.5 | H17: =IF(A17>$B$7,"Infeasible","Feasible") -> Feasible
A18: 2.5 | B18: =IF(A18>$B$7,"",IF(A18<=$B$6,10,2*A18-85)) -> 10 | C18: =IF(A18>$B$7,"",IF(A18<=$B$5,10,IF(A18<=$B$6,A18-20,75-A18))) -> 10 | D18: =IF(A18>$B$7,"",10) -> 10 | E18: =IF(A18>$B$7,"",SUMPRODUCT(B18:D18,'P1 Lunch'!$B$5:$D$5)) -> 80 | F18: =IF(A18>$B$7,"",SUMPRODUCT(B18:D18,'P1 Lunch'!$B$6:$D$6)) -> 70 | G18: =IF(A18>$B$7,"",SUMPRODUCT(B18:D18,'P1 Lunch'!$B$7:$D$7)) -> 4.5 | H18: =IF(A18>$B$7,"Infeasible","Feasible") -> Feasible
A19: 3 | B19: =IF(A19>$B$7,"",IF(A19<=$B$6,10,2*A19-85)) -> 10 | C19: =IF(A19>$B$7,"",IF(A19<=$B$5,10,IF(A19<=$B$6,A19-20,75-A19))) -> 10 | D19: =IF(A19>$B$7,"",10) -> 10 | E19: =IF(A19>$B$7,"",SUMPRODUCT(B19:D19,'P1 Lunch'!$B$5:$D$5)) -> 80 | F19: =IF(A19>$B$7,"",SUMPRODUCT(B19:D19,'P1 Lunch'!$B$6:$D$6)) -> 70 | G19: =IF(A19>$B$7,"",SUMPRODUCT(B19:D19,'P1 Lunch'!$B$7:$D$7)) -> 4.5 | H19: =IF(A19>$B$7,"Infeasible","Feasible") -> Feasible
A20: 3.5 | B20: =IF(A20>$B$7,"",IF(A20<=$B$6,10,2*A20-85)) -> 10 | C20: =IF(A20>$B$7,"",IF(A20<=$B$5,10,IF(A20<=$B$6,A20-20,75-A20))) -> 10 | D20: =IF(A20>$B$7,"",10) -> 10 | E20: =IF(A20>$B$7,"",SUMPRODUCT(B20:D20,'P1 Lunch'!$B$5:$D$5)) -> 80 | F20: =IF(A20>$B$7,"",SUMPRODUCT(B20:D20,'P1 Lunch'!$B$6:$D$6)) -> 70 | G20: =IF(A20>$B$7,"",SUMPRODUCT(B20:D20,'P1 Lunch'!$B$7:$D$7)) -> 4.5 | H20: =IF(A20>$B$7,"Infeasible","Feasible") -> Feasible
A21: 4 | B21: =IF(A21>$B$7,"",IF(A21<=$B$6,10,2*A21-85)) -> 10 | C21: =IF(A21>$B$7,"",IF(A21<=$B$5,10,IF(A21<=$B$6,A21-20,75-A21))) -> 10 | D21: =IF(A21>$B$7,"",10) -> 10 | E21: =IF(A21>$B$7,"",SUMPRODUCT(B21:D21,'P1 Lunch'!$B$5:$D$5)) -> 80 | F21: =IF(A21>$B$7,"",SUMPRODUCT(B21:D21,'P1 Lunch'!$B$6:$D$6)) -> 70 | G21: =IF(A21>$B$7,"",SUMPRODUCT(B21:D21,'P1 Lunch'!$B$7:$D$7)) -> 4.5 | H21: =IF(A21>$B$7,"Infeasible","Feasible") -> Feasible
A22: 4.5 | B22: =IF(A22>$B$7,"",IF(A22<=$B$6,10,2*A22-85)) -> 10 | C22: =IF(A22>$B$7,"",IF(A22<=$B$5,10,IF(A22<=$B$6,A22-20,75-A22))) -> 10 | D22: =IF(A22>$B$7,"",10) -> 10 | E22: =IF(A22>$B$7,"",SUMPRODUCT(B22:D22,'P1 Lunch'!$B$5:$D$5)) -> 80 | F22: =IF(A22>$B$7,"",SUMPRODUCT(B22:D22,'P1 Lunch'!$B$6:$D$6)) -> 70 | G22: =IF(A22>$B$7,"",SUMPRODUCT(B22:D22,'P1 Lunch'!$B$7:$D$7)) -> 4.5 | H22: =IF(A22>$B$7,"Infeasible","Feasible") -> Feasible
A23: 5 | B23: =IF(A23>$B$7,"",IF(A23<=$B$6,10,2*A23-85)) -> 10 | C23: =IF(A23>$B$7,"",IF(A23<=$B$5,10,IF(A23<=$B$6,A23-20,75-A23))) -> 10 | D23: =IF(A23>$B$7,"",10) -> 10 | E23: =IF(A23>$B$7,"",SUMPRODUCT(B23:D23,'P1 Lunch'!$B$5:$D$5)) -> 80 | F23: =IF(A23>$B$7,"",SUMPRODUCT(B23:D23,'P1 Lunch'!$B$6:$D$6)) -> 70 | G23: =IF(A23>$B$7,"",SUMPRODUCT(B23:D23,'P1 Lunch'!$B$7:$D$7)) -> 4.5 | H23: =IF(A23>$B$7,"Infeasible","Feasible") -> Feasible
A24: 5.5 | B24: =IF(A24>$B$7,"",IF(A24<=$B$6,10,2*A24-85)) -> 10 | C24: =IF(A24>$B$7,"",IF(A24<=$B$5,10,IF(A24<=$B$6,A24-20,75-A24))) -> 10 | D24: =IF(A24>$B$7,"",10) -> 10 | E24: =IF(A24>$B$7,"",SUMPRODUCT(B24:D24,'P1 Lunch'!$B$5:$D$5)) -> 80 | F24: =IF(A24>$B$7,"",SUMPRODUCT(B24:D24,'P1 Lunch'!$B$6:$D$6)) -> 70 | G24: =IF(A24>$B$7,"",SUMPRODUCT(B24:D24,'P1 Lunch'!$B$7:$D$7)) -> 4.5 | H24: =IF(A24>$B$7,"Infeasible","Feasible") -> Feasible
... A144: 66 | B144: =IF(A144>$B$7,"",IF(A144<=$B$6,10,2*A144-85)) | C144: =IF(A144>$B$7,"",IF(A144<=$B$5,10,IF(A144<=$B$6,A144-20,75-A144))) | D144: =IF(A144>$B$7,"",10) | E144: =IF(A144>$B$7,"",SUMPRODUCT(B144:D144,'P1 Lunch'!$B$5:$D$5)) | F144: =IF(A144>$B$7,"",SUMPRODUCT(B144:D144,'P1 Lunch'!$B$6:$D$6)) | G144: =IF(A144>$B$7,"",SUMPRODUCT(B144:D144,'P1 Lunch'!$B$7:$D$7)) | H144: =IF(A144>$B$7,"Infeasible","Feasible") -> Infeasible

Sheet P2
A1: Problem 2 | Sensitivity statements
A4: Part | B4: Answer | C4: Justification
A5: a | B5: True | C5: For an optimal continuous LP, positive slack implies a zero dual multiplier by complementary slackness.
A6: b | B6: False | C6: Counterexample: minimize x1 subject to x1 >= 1 and 0 <= x2 <= 1. Every (1,x2) is optimal, yet only x2 has a zero allowable coefficient change in at least one direction.
A7: c | B7: False | C7: The joint RHS change is not guaranteed by separate ranges: 1/2 + 1/1 = 150%, exceeding the 100% rule. The objective might change by $8, but this report alone cannot establish it.
A8: d | B8: False | C8: Resource 1 RHS can rise only to 12 under the stated shadow price; 14 exceeds that range. A $20 increase cannot be inferred.
A9: e | B9: False | C9: The $3 marginal applies only while Resource 2 RHS is in [3,9], holding other data fixed. It is not valid for every additional unit indefinitely.
A10: f | B10: True | C10: Final LHS equals RHS for both resources: 10=10 and 8=8; therefore both are binding.
A13: Resource | B13: Final LHS | C13: Shadow price | D13: RHS | E13: Allow. increase | F13: Allow. decrease | G13: Unit cost
A14: Resource 1 | B14: 10 | C14: 5 | D14: 10 | E14: 2 | F14: 4 | G14: 5
A15: Resource 2 | B15: 8 | C15: 3 | D15: 8 | E15: 1 | F15: 5 | G15: 4
A17: Joint-change ratio | B17: =1/E14+1/E15 -> 1.5
A19: The stated resource purchase costs do not extend sensitivity ranges. If this is profit before new resource purchases, an extra unit yields net gain $0 for Resource 1 and -$1 for Resource 2, within valid one-at-a-time ranges.

Sheet P3 Base
A1: Problem 3 | Base flight network
A3: Direct flights allowed from: none. Each row preserves one origin-destination demand.
A5: Origin | B5: Destination | C5: Demand | D5: Via Chicago | E5: Via Atlanta | F5: Direct | G5: Assigned | H5: Residual | I5: Cost Chicago | J5: Cost Atlanta | K5: Cost direct | L5: Row cost
A6: Pittsburgh | B6: Miami | C6: 100 | D6: 50 | E6: 50 | F6: 0 | G6: =SUM(D6:F6) -> 100 | H6: =G6-C6 -> 0 | I6: =$D$19+$D$25 -> 150 | J6: =$D$20+$D$28 -> 180 | K6: 120 | L6: =SUMPRODUCT(D6:F6,I6:K6) -> 16500
A7: Pittsburgh | B7: Orlando | C7: 60 | D7: 60 | E7: 0 | F7: 0 | G7: =SUM(D7:F7) -> 60 | H7: =G7-C7 -> 0 | I7: =$D$19+$D$26 -> 140 | J7: =$D$20+$D$29 -> 170 | K7: 80 | L7: =SUMPRODUCT(D7:F7,I7:K7) -> 8400
A8: Pittsburgh | B8: New York | C8: 40 | D8: 40 | E8: 0 | F8: 0 | G8: =SUM(D8:F8) -> 40 | H8: =G8-C8 -> 0 | I8: =$D$19+$D$27 -> 130 | J8: =$D$20+$D$30 -> 200 | K8: 70 | L8: =SUMPRODUCT(D8:F8,I8:K8) -> 5200
A9: Cleveland | B9: Miami | C9: 50 | D9: 0 | E9: 50 | F9: 0 | G9: =SUM(D9:F9) -> 50 | H9: =G9-C9 -> 0 | I9: =$D$21+$D$25 -> 160 | J9: =$D$22+$D$28 -> 170 | K9: 110 | L9: =SUMPRODUCT(D9:F9,I9:K9) -> 8500
A10: Cleveland | B10: Orlando | C10: 50 | D10: 50 | E10: 0 | F10: 0 | G10: =SUM(D10:F10) -> 50 | H10: =G10-C10 -> 0 | I10: =$D$21+$D$26 -> 150 | J10: =$D$22+$D$29 -> 160 | K10: 75 | L10: =SUMPRODUCT(D10:F10,I10:K10) -> 7500
A11: Cleveland | B11: New York | C11: 50 | D11: 50 | E11: 0 | F11: 0 | G11: =SUM(D11:F11) -> 50 | H11: =G11-C11 -> 0 | I11: =$D$21+$D$27 -> 140 | J11: =$D$22+$D$30 -> 190 | K11: 65 | L11: =SUMPRODUCT(D11:F11,I11:K11) -> 7000
A12: Columbus | B12: Miami | C12: 0 | D12: 0 | E12: 0 | F12: 0 | G12: =SUM(D12:F12) -> 0 | H12: =G12-C12 -> 0 | I12: =$D$23+$D$25 -> 170 | J12: =$D$24+$D$28 -> 160 | K12: 100 | L12: =SUMPRODUCT(D12:F12,I12:K12) -> 0
A13: Columbus | B13: Orlando | C13: 40 | D13: 10 | E13: 30 | F13: 0 | G13: =SUM(D13:F13) -> 40 | H13: =G13-C13 -> 0 | I13: =$D$23+$D$26 -> 160 | J13: =$D$24+$D$29 -> 150 | K13: 70 | L13: =SUMPRODUCT(D13:F13,I13:K13) -> 6100
A14: Columbus | B14: New York | C14: 60 | D14: 10 | E14: 50 | F14: 0 | G14: =SUM(D14:F14) -> 60 | H14: =G14-C14 -> 0 | I14: =$D$23+$D$27 -> 150 | J14: =$D$24+$D$30 -> 180 | K14: 60 | L14: =SUMPRODUCT(D14:F14,I14:K14) -> 10500
A16: Total cost | B16: =SUM(L6:L14) -> 69700
A18: Arc origin | B18: Arc destination | C18: Capacity | D18: Unit cost | E18: Flow | F18: Slack
A19: Pittsburgh | B19: Chicago | C19: 150 | D19: 50 | E19: =SUM(D6:D8) -> 150 | F19: =C19-E19 -> 0
A20: Pittsburgh | B20: Atlanta | C20: 100 | D20: 100 | E20: =SUM(E6:E8) -> 50 | F20: =C20-E20 -> 50
A21: Cleveland | B21: Chicago | C21: 100 | D21: 60 | E21: =SUM(D9:D11) -> 100 | F21: =C21-E21 -> 0
A22: Cleveland | B22: Atlanta | C22: 100 | D22: 90 | E22: =SUM(E9:E11) -> 50 | F22: =C22-E22 -> 50
A23: Columbus | B23: Chicago | C23: 100 | D23: 70 | E23: =SUM(D12:D14) -> 20 | F23: =C23-E23 -> 80
A24: Columbus | B24: Atlanta | C24: 80 | D24: 80 | E24: =SUM(E12:E14) -> 80 | F24: =C24-E24 -> 0
A25: Chicago | B25: Miami | C25: 150 | D25: 100 | E25: =D6+D9+D12 -> 50 | F25: =C25-E25 -> 100
A26: Chicago | B26: Orlando | C26: 120 | D26: 90 | E26: =D7+D10+D13 -> 120 | F26: =C26-E26 -> 0
A27: Chicago | B27: New York | C27: 100 | D27: 80 | E27: =D8+D11+D14 -> 100 | F27: =C27-E27 -> 0
A28: Atlanta | B28: Miami | C28: 120 | D28: 80 | E28: =E6+E9+E12 -> 100 | F28: =C28-E28 -> 20
A29: Atlanta | B29: Orlando | C29: 150 | D29: 70 | E29: =E7+E10+E13 -> 30 | F29: =C29-E29 -> 120
A30: Atlanta | B30: New York | C30: 120 | D30: 100 | E30: =E8+E11+E14 -> 50 | F30: =C30-E30 -> 70
A32: Direct origin | B32: Destination | C32: Allowed capacity | D32: Flow | E32: Slack
A33: Pittsburgh | B33: Miami | C33: 0 | D33: =F6 -> 0 | E33: =C33-D33 -> 0
A34: Pittsburgh | B34: Orlando | C34: 0 | D34: =F7 -> 0 | E34: =C34-D34 -> 0
A35: Pittsburgh | B35: New York | C35: 0 | D35: =F8 -> 0 | E35: =C35-D35 -> 0
A36: Cleveland | B36: Miami | C36: 0 | D36: =F9 -> 0 | E36: =C36-D36 -> 0
A37: Cleveland | B37: Orlando | C37: 0 | D37: =F10 -> 0 | E37: =C37-D37 -> 0
A38: Cleveland | B38: New York | C38: 0 | D38: =F11 -> 0 | E38: =C38-D38 -> 0
A39: Columbus | B39: Miami | C39: 0 | D39: =F12 -> 0 | E39: =C39-D39 -> 0
A40: Columbus | B40: Orlando | C40: 0 | D40: =F13 -> 0 | E40: =C40-D40 -> 0
A41: Columbus | B41: New York | C41: 0 | D41: =F14 -> 0 | E41: =C41-D41 -> 0
A43: Solver setting | B43: Specification
A44: Objective $B$16, Min; changing cells $D$6:$F$14; Simplex LP; non-negative variables.
A45: Constraints: $G$6:$G$14 = $C$6:$C$14; $E$19:$E$30 <= $C$19:$C$30; $D$33:$D$41 <= $C$33:$C$41.
A46: Connecting path costs = first-leg cost + second-leg cost. Flow formulas aggregate all OD passengers using each flight. Capacities and OD demands stay fixed across scenarios.
...

Sheet P3 Pittsburgh
A1: Problem 3 | Pittsburgh flight network
A3: Direct flights allowed from: Pittsburgh. Each row preserves one origin-destination demand.
A5: Origin | B5: Destination | C5: Demand | D5: Via Chicago | E5: Via Atlanta | F5: Direct | G5: Assigned | H5: Residual | I5: Cost Chicago | J5: Cost Atlanta | K5: Cost direct | L5: Row cost
A6: Pittsburgh | B6: Miami | C6: 100 | D6: 0 | E6: 0 | F6: 100 | G6: =SUM(D6:F6) -> 100 | H6: =G6-C6 -> 0 | I6: =$D$19+$D$25 -> 150 | J6: =$D$20+$D$28 -> 180 | K6: 120 | L6: =SUMPRODUCT(D6:F6,I6:K6) -> 12000
A7: Pittsburgh | B7: Orlando | C7: 60 | D7: 0 | E7: 0 | F7: 60 | G7: =SUM(D7:F7) -> 60 | H7: =G7-C7 -> 0 | I7: =$D$19+$D$26 -> 140 | J7: =$D$20+$D$29 -> 170 | K7: 80 | L7: =SUMPRODUCT(D7:F7,I7:K7) -> 4800
A8: Pittsburgh | B8: New York | C8: 40 | D8: 0 | E8: 0 | F8: 40 | G8: =SUM(D8:F8) -> 40 | H8: =G8-C8 -> 0 | I8: =$D$19+$D$27 -> 130 | J8: =$D$20+$D$30 -> 200 | K8: 70 | L8: =SUMPRODUCT(D8:F8,I8:K8) -> 2800
A9: Cleveland | B9: Miami | C9: 50 | D9: 0 | E9: 50 | F9: 0 | G9: =SUM(D9:F9) -> 50 | H9: =G9-C9 -> 0 | I9: =$D$21+$D$25 -> 160 | J9: =$D$22+$D$28 -> 170 | K9: 110 | L9: =SUMPRODUCT(D9:F9,I9:K9) -> 8500
A10: Cleveland | B10: Orlando | C10: 50 | D10: 50 | E10: 0 | F10: 0 | G10: =SUM(D10:F10) -> 50 | H10: =G10-C10 -> 0 | I10: =$D$21+$D$26 -> 150 | J10: =$D$22+$D$29 -> 160 | K10: 75 | L10: =SUMPRODUCT(D10:F10,I10:K10) -> 7500
A11: Cleveland | B11: New York | C11: 50 | D11: 50 | E11: 0 | F11: 0 | G11: =SUM(D11:F11) -> 50 | H11: =G11-C11 -> 0 | I11: =$D$21+$D$27 -> 140 | J11: =$D$22+$D$30 -> 190 | K11: 65 | L11: =SUMPRODUCT(D11:F11,I11:K11) -> 7000
A12: Columbus | B12: Miami | C12: 0 | D12: 0 | E12: 0 | F12: 0 | G12: =SUM(D12:F12) -> 0 | H12: =G12-C12 -> 0 | I12: =$D$23+$D$25 -> 170 | J12: =$D$24+$D$28 -> 160 | K12: 100 | L12: =SUMPRODUCT(D12:F12,I12:K12) -> 0
A13: Columbus | B13: Orlando | C13: 40 | D13: 0 | E13: 40 | F13: 0 | G13: =SUM(D13:F13) -> 40 | H13: =G13-C13 -> 0 | I13: =$D$23+$D$26 -> 160 | J13: =$D$24+$D$29 -> 150 | K13: 70 | L13: =SUMPRODUCT(D13:F13,I13:K13) -> 6000
A14: Columbus | B14: New York | C14: 60 | D14: 50 | E14: 10 | F14: 0 | G14: =SUM(D14:F14) -> 60 | H14: =G14-C14 -> 0 | I14: =$D$23+$D$27 -> 150 | J14: =$D$24+$D$30 -> 180 | K14: 60 | L14: =SUMPRODUCT(D14:F14,I14:K14) -> 9300
A16: Total cost | B16: =SUM(L6:L14) -> 57900
A18: Arc origin | B18: Arc destination | C18: Capacity | D18: Unit cost | E18: Flow | F18: Slack
A19: Pittsburgh | B19: Chicago | C19: 150 | D19: 50 | E19: =SUM(D6:D8) -> 0 | F19: =C19-E19 -> 150
A20: Pittsburgh | B20: Atlanta | C20: 100 | D20: 100 | E20: =SUM(E6:E8) -> 0 | F20: =C20-E20 -> 100
A21: Cleveland | B21: Chicago | C21: 100 | D21: 60 | E21: =SUM(D9:D11) -> 100 | F21: =C21-E21 -> 0
A22: Cleveland | B22: Atlanta | C22: 100 | D22: 90 | E22: =SUM(E9:E11) -> 50 | F22: =C22-E22 -> 50
A23: Columbus | B23: Chicago | C23: 100 | D23: 70 | E23: =SUM(D12:D14) -> 50 | F23: =C23-E23 -> 50
A24: Columbus | B24: Atlanta | C24: 80 | D24: 80 | E24: =SUM(E12:E14) -> 50 | F24: =C24-E24 -> 30
A25: Chicago | B25: Miami | C25: 150 | D25: 100 | E25: =D6+D9+D12 -> 0 | F25: =C25-E25 -> 150
A26: Chicago | B26: Orlando | C26: 120 | D26: 90 | E26: =D7+D10+D13 -> 50 | F26: =C26-E26 -> 70
A27: Chicago | B27: New York | C27: 100 | D27: 80 | E27: =D8+D11+D14 -> 100 | F27: =C27-E27 -> 0
A28: Atlanta | B28: Miami | C28: 120 | D28: 80 | E28: =E6+E9+E12 -> 50 | F28: =C28-E28 -> 70
A29: Atlanta | B29: Orlando | C29: 150 | D29: 70 | E29: =E7+E10+E13 -> 40 | F29: =C29-E29 -> 110
A30: Atlanta | B30: New York | C30: 120 | D30: 100 | E30: =E8+E11+E14 -> 10 | F30: =C30-E30 -> 110
A32: Direct origin | B32: Destination | C32: Allowed capacity | D32: Flow | E32: Slack
A33: Pittsburgh | B33: Miami | C33: 100 | D33: =F6 -> 100 | E33: =C33-D33 -> 0
A34: Pittsburgh | B34: Orlando | C34: 60 | D34: =F7 -> 60 | E34: =C34-D34 -> 0
A35: Pittsburgh | B35: New York | C35: 40 | D35: =F8 -> 40 | E35: =C35-D35 -> 0
A36: Cleveland | B36: Miami | C36: 0 | D36: =F9 -> 0 | E36: =C36-D36 -> 0
A37: Cleveland | B37: Orlando | C37: 0 | D37: =F10 -> 0 | E37: =C37-D37 -> 0
A38: Cleveland | B38: New York | C38: 0 | D38: =F11 -> 0 | E38: =C38-D38 -> 0
A39: Columbus | B39: Miami | C39: 0 | D39: =F12 -> 0 | E39: =C39-D39 -> 0
A40: Columbus | B40: Orlando | C40: 0 | D40: =F13 -> 0 | E40: =C40-D40 -> 0
A41: Columbus | B41: New York | C41: 0 | D41: =F14 -> 0 | E41: =C41-D41 -> 0
A43: Solver setting | B43: Specification
A44: Objective $B$16, Min; changing cells $D$6:$F$14; Simplex LP; non-negative variables.
A45: Constraints: $G$6:$G$14 = $C$6:$C$14; $E$19:$E$30 <= $C$19:$C$30; $D$33:$D$41 <= $C$33:$C$41.
A46: Connecting path costs = first-leg cost + second-leg cost. Flow formulas aggregate all OD passengers using each flight. Capacities and OD demands stay fixed across scenarios.
...

Sheet P3 Cleveland
A1: Problem 3 | Cleveland flight network
A3: Direct flights allowed from: Cleveland. Each row preserves one origin-destination demand.
A5: Origin | B5: Destination | C5: Demand | D5: Via Chicago | E5: Via Atlanta | F5: Direct | G5: Assigned | H5: Residual | I5: Cost Chicago | J5: Cost Atlanta | K5: Cost direct | L5: Row cost
A6: Pittsburgh | B6: Miami | C6: 100 | D6: 50 | E6: 50 | F6: 0 | G6: =SUM(D6:F6) -> 100 | H6: =G6-C6 -> 0 | I6: =$D$19+$D$25 -> 150 | J6: =$D$20+$D$28 -> 180 | K6: 120 | L6: =SUMPRODUCT(D6:F6,I6:K6) -> 16500
A7: Pittsburgh | B7: Orlando | C7: 60 | D7: 60 | E7: 0 | F7: 0 | G7: =SUM(D7:F7) -> 60 | H7: =G7-C7 -> 0 | I7: =$D$19+$D$26 -> 140 | J7: =$D$20+$D$29 -> 170 | K7: 80 | L7: =SUMPRODUCT(D7:F7,I7:K7) -> 8400
A8: Pittsburgh | B8: New York | C8: 40 | D8: 40 | E8: 0 | F8: 0 | G8: =SUM(D8:F8) -> 40 | H8: =G8-C8 -> 0 | I8: =$D$19+$D$27 -> 130 | J8: =$D$20+$D$30 -> 200 | K8: 70 | L8: =SUMPRODUCT(D8:F8,I8:K8) -> 5200
A9: Cleveland | B9: Miami | C9: 50 | D9: 0 | E9: 0 | F9: 50 | G9: =SUM(D9:F9) -> 50 | H9: =G9-C9 -> 0 | I9: =$D$21+$D$25 -> 160 | J9: =$D$22+$D$28 -> 170 | K9: 110 | L9: =SUMPRODUCT(D9:F9,I9:K9) -> 5500
A10: Cleveland | B10: Orlando | C10: 50 | D10: 0 | E10: 0 | F10: 50 | G10: =SUM(D10:F10) -> 50 | H10: =G10-C10 -> 0 | I10: =$D$21+$D$26 -> 150 | J10: =$D$22+$D$29 -> 160 | K10: 75 | L10: =SUMPRODUCT(D10:F10,I10:K10) -> 3750
A11: Cleveland | B11: New York | C11: 50 | D11: 0 | E11: 0 | F11: 50 | G11: =SUM(D11:F11) -> 50 | H11: =G11-C11 -> 0 | I11: =$D$21+$D$27 -> 140 | J11: =$D$22+$D$30 -> 190 | K11: 65 | L11: =SUMPRODUCT(D11:F11,I11:K11) -> 3250
A12: Columbus | B12: Miami | C12: 0 | D12: 0 | E12: 0 | F12: 0 | G12: =SUM(D12:F12) -> 0 | H12: =G12-C12 -> 0 | I12: =$D$23+$D$25 -> 170 | J12: =$D$24+$D$28 -> 160 | K12: 100 | L12: =SUMPRODUCT(D12:F12,I12:K12) -> 0
A13: Columbus | B13: Orlando | C13: 40 | D13: 0 | E13: 40 | F13: 0 | G13: =SUM(D13:F13) -> 40 | H13: =G13-C13 -> 0 | I13: =$D$23+$D$26 -> 160 | J13: =$D$24+$D$29 -> 150 | K13: 70 | L13: =SUMPRODUCT(D13:F13,I13:K13) -> 6000
A14: Columbus | B14: New York | C14: 60 | D14: 60 | E14: 0 | F14: 0 | G14: =SUM(D14:F14) -> 60 | H14: =G14-C14 -> 0 | I14: =$D$23+$D$27 -> 150 | J14: =$D$24+$D$30 -> 180 | K14: 60 | L14: =SUMPRODUCT(D14:F14,I14:K14) -> 9000
A16: Total cost | B16: =SUM(L6:L14) -> 57600
A18: Arc origin | B18: Arc destination | C18: Capacity | D18: Unit cost | E18: Flow | F18: Slack
A19: Pittsburgh | B19: Chicago | C19: 150 | D19: 50 | E19: =SUM(D6:D8) -> 150 | F19: =C19-E19 -> 0
A20: Pittsburgh | B20: Atlanta | C20: 100 | D20: 100 | E20: =SUM(E6:E8) -> 50 | F20: =C20-E20 -> 50
A21: Cleveland | B21: Chicago | C21: 100 | D21: 60 | E21: =SUM(D9:D11) -> 0 | F21: =C21-E21 -> 100
A22: Cleveland | B22: Atlanta | C22: 100 | D22: 90 | E22: =SUM(E9:E11) -> 0 | F22: =C22-E22 -> 100
A23: Columbus | B23: Chicago | C23: 100 | D23: 70 | E23: =SUM(D12:D14) -> 60 | F23: =C23-E23 -> 40
A24: Columbus | B24: Atlanta | C24: 80 | D24: 80 | E24: =SUM(E12:E14) -> 40 | F24: =C24-E24 -> 40
A25: Chicago | B25: Miami | C25: 150 | D25: 100 | E25: =D6+D9+D12 -> 50 | F25: =C25-E25 -> 100
A26: Chicago | B26: Orlando | C26: 120 | D26: 90 | E26: =D7+D10+D13 -> 60 | F26: =C26-E26 -> 60
A27: Chicago | B27: New York | C27: 100 | D27: 80 | E27: =D8+D11+D14 -> 100 | F27: =C27-E27 -> 0
A28: Atlanta | B28: Miami | C28: 120 | D28: 80 | E28: =E6+E9+E12 -> 50 | F28: =C28-E28 -> 70
A29: Atlanta | B29: Orlando | C29: 150 | D29: 70 | E29: =E7+E10+E13 -> 40 | F29: =C29-E29 -> 110
A30: Atlanta | B30: New York | C30: 120 | D30: 100 | E30: =E8+E11+E14 -> 0 | F30: =C30-E30 -> 120
A32: Direct origin | B32: Destination | C32: Allowed capacity | D32: Flow | E32: Slack
A33: Pittsburgh | B33: Miami | C33: 0 | D33: =F6 -> 0 | E33: =C33-D33 -> 0
A34: Pittsburgh | B34: Orlando | C34: 0 | D34: =F7 -> 0 | E34: =C34-D34 -> 0
A35: Pittsburgh | B35: New York | C35: 0 | D35: =F8 -> 0 | E35: =C35-D35 -> 0
A36: Cleveland | B36: Miami | C36: 100 | D36: =F9 -> 50 | E36: =C36-D36 -> 50
A37: Cleveland | B37: Orlando | C37: 60 | D37: =F10 -> 50 | E37: =C37-D37 -> 10
A38: Cleveland | B38: New York | C38: 50 | D38: =F11 -> 50 | E38: =C38-D38 -> 0
A39: Columbus | B39: Miami | C39: 0 | D39: =F12 -> 0 | E39: =C39-D39 -> 0
A40: Columbus | B40: Orlando | C40: 0 | D40: =F13 -> 0 | E40: =C40-D40 -> 0
A41: Columbus | B41: New York | C41: 0 | D41: =F14 -> 0 | E41: =C41-D41 -> 0
A43: Solver setting | B43: Specification
A44: Objective $B$16, Min; changing cells $D$6:$F$14; Simplex LP; non-negative variables.
A45: Constraints: $G$6:$G$14 = $C$6:$C$14; $E$19:$E$30 <= $C$19:$C$30; $D$33:$D$41 <= $C$33:$C$41.
A46: Connecting path costs = first-leg cost + second-leg cost. Flow formulas aggregate all OD passengers using each flight. Capacities and OD demands stay fixed across scenarios.
...

Sheet P3 Columbus
A1: Problem 3 | Columbus flight network
A3: Direct flights allowed from: Columbus. Each row preserves one origin-destination demand.
A5: Origin | B5: Destination | C5: Demand | D5: Via Chicago | E5: Via Atlanta | F5: Direct | G5: Assigned | H5: Residual | I5: Cost Chicago | J5: Cost Atlanta | K5: Cost direct | L5: Row cost
A6: Pittsburgh | B6: Miami | C6: 100 | D6: 50 | E6: 50 | F6: 0 | G6: =SUM(D6:F6) -> 100 | H6: =G6-C6 -> 0 | I6: =$D$19+$D$25 -> 150 | J6: =$D$20+$D$28 -> 180 | K6: 120 | L6: =SUMPRODUCT(D6:F6,I6:K6) -> 16500
A7: Pittsburgh | B7: Orlando | C7: 60 | D7: 60 | E7: 0 | F7: 0 | G7: =SUM(D7:F7) -> 60 | H7: =G7-C7 -> 0 | I7: =$D$19+$D$26 -> 140 | J7: =$D$20+$D$29 -> 170 | K7: 80 | L7: =SUMPRODUCT(D7:F7,I7:K7) -> 8400
A8: Pittsburgh | B8: New York | C8: 40 | D8: 40 | E8: 0 | F8: 0 | G8: =SUM(D8:F8) -> 40 | H8: =G8-C8 -> 0 | I8: =$D$19+$D$27 -> 130 | J8: =$D$20+$D$30 -> 200 | K8: 70 | L8: =SUMPRODUCT(D8:F8,I8:K8) -> 5200
A9: Cleveland | B9: Miami | C9: 50 | D9: 0 | E9: 50 | F9: 0 | G9: =SUM(D9:F9) -> 50 | H9: =G9-C9 -> 0 | I9: =$D$21+$D$25 -> 160 | J9: =$D$22+$D$28 -> 170 | K9: 110 | L9: =SUMPRODUCT(D9:F9,I9:K9) -> 8500
A10: Cleveland | B10: Orlando | C10: 50 | D10: 50 | E10: 0 | F10: 0 | G10: =SUM(D10:F10) -> 50 | H10: =G10-C10 -> 0 | I10: =$D$21+$D$26 -> 150 | J10: =$D$22+$D$29 -> 160 | K10: 75 | L10: =SUMPRODUCT(D10:F10,I10:K10) -> 7500
A11: Cleveland | B11: New York | C11: 50 | D11: 50 | E11: 0 | F11: 0 | G11: =SUM(D11:F11) -> 50 | H11: =G11-C11 -> 0 | I11: =$D$21+$D$27 -> 140 | J11: =$D$22+$D$30 -> 190 | K11: 65 | L11: =SUMPRODUCT(D11:F11,I11:K11) -> 7000
A12: Columbus | B12: Miami | C12: 0 | D12: 0 | E12: 0 | F12: 0 | G12: =SUM(D12:F12) -> 0 | H12: =G12-C12 -> 0 | I12: =$D$23+$D$25 -> 170 | J12: =$D$24+$D$28 -> 160 | K12: 100 | L12: =SUMPRODUCT(D12:F12,I12:K12) -> 0
A13: Columbus | B13: Orlando | C13: 40 | D13: 0 | E13: 0 | F13: 40 | G13: =SUM(D13:F13) -> 40 | H13: =G13-C13 -> 0 | I13: =$D$23+$D$26 -> 160 | J13: =$D$24+$D$29 -> 150 | K13: 70 | L13: =SUMPRODUCT(D13:F13,I13:K13) -> 2800
A14: Columbus | B14: New York | C14: 60 | D14: 0 | E14: 0 | F14: 60 | G14: =SUM(D14:F14) -> 60 | H14: =G14-C14 -> 0 | I14: =$D$23+$D$27 -> 150 | J14: =$D$24+$D$30 -> 180 | K14: 60 | L14: =SUMPRODUCT(D14:F14,I14:K14) -> 3600
A16: Total cost | B16: =SUM(L6:L14) -> 59500
A18: Arc origin | B18: Arc destination | C18: Capacity | D18: Unit cost | E18: Flow | F18: Slack
A19: Pittsburgh | B19: Chicago | C19: 150 | D19: 50 | E19: =SUM(D6:D8) -> 150 | F19: =C19-E19 -> 0
A20: Pittsburgh | B20: Atlanta | C20: 100 | D20: 100 | E20: =SUM(E6:E8) -> 50 | F20: =C20-E20 -> 50
A21: Cleveland | B21: Chicago | C21: 100 | D21: 60 | E21: =SUM(D9:D11) -> 100 | F21: =C21-E21 -> 0
A22: Cleveland | B22: Atlanta | C22: 100 | D22: 90 | E22: =SUM(E9:E11) -> 50 | F22: =C22-E22 -> 50
A23: Columbus | B23: Chicago | C23: 100 | D23: 70 | E23: =SUM(D12:D14) -> 0 | F23: =C23-E23 -> 100
A24: Columbus | B24: Atlanta | C24: 80 | D24: 80 | E24: =SUM(E12:E14) -> 0 | F24: =C24-E24 -> 80
A25: Chicago | B25: Miami | C25: 150 | D25: 100 | E25: =D6+D9+D12 -> 50 | F25: =C25-E25 -> 100
A26: Chicago | B26: Orlando | C26: 120 | D26: 90 | E26: =D7+D10+D13 -> 110 | F26: =C26-E26 -> 10
A27: Chicago | B27: New York | C27: 100 | D27: 80 | E27: =D8+D11+D14 -> 90 | F27: =C27-E27 -> 10
A28: Atlanta | B28: Miami | C28: 120 | D28: 80 | E28: =E6+E9+E12 -> 100 | F28: =C28-E28 -> 20
A29: Atlanta | B29: Orlando | C29: 150 | D29: 70 | E29: =E7+E10+E13 -> 0 | F29: =C29-E29 -> 150
A30: Atlanta | B30: New York | C30: 120 | D30: 100 | E30: =E8+E11+E14 -> 0 | F30: =C30-E30 -> 120
A32: Direct origin | B32: Destination | C32: Allowed capacity | D32: Flow | E32: Slack
A33: Pittsburgh | B33: Miami | C33: 0 | D33: =F6 -> 0 | E33: =C33-D33 -> 0
A34: Pittsburgh | B34: Orlando | C34: 0 | D34: =F7 -> 0 | E34: =C34-D34 -> 0
A35: Pittsburgh | B35: New York | C35: 0 | D35: =F8 -> 0 | E35: =C35-D35 -> 0
A36: Cleveland | B36: Miami | C36: 0 | D36: =F9 -> 0 | E36: =C36-D36 -> 0
A37: Cleveland | B37: Orlando | C37: 0 | D37: =F10 -> 0 | E37: =C37-D37 -> 0
A38: Cleveland | B38: New York | C38: 0 | D38: =F11 -> 0 | E38: =C38-D38 -> 0
A39: Columbus | B39: Miami | C39: 80 | D39: =F12 -> 0 | E39: =C39-D39 -> 80
A40: Columbus | B40: Orlando | C40: 40 | D40: =F13 -> 40 | E40: =C40-D40 -> 0
A41: Columbus | B41: New York | C41: 60 | D41: =F14 -> 60 | E41: =C41-D41 -> 0
A43: Solver setting | B43: Specification
A44: Objective $B$16, Min; changing cells $D$6:$F$14; Simplex LP; non-negative variables.
A45: Constraints: $G$6:$G$14 = $C$6:$C$14; $E$19:$E$30 <= $C$19:$C$30; $D$33:$D$41 <= $C$33:$C$41.
A46: Connecting path costs = first-leg cost + second-leg cost. Flow formulas aggregate all OD passengers using each flight. Capacities and OD demands stay fixed across scenarios.
...

Sheet P4 Mentoring
A1: Problem 4 | Mentor assignment
A4: Score: mentor / mentee | B4: Alice | C4: Ben | D4: Carlos | E4: Diana | F4: Emma | G4: Frank
A5: Alice | B5: 0 | C5: 5 | D5: 10 | E5: 100 | F5: 95 | G5: 85
A6: Ben | B6: 65 | C6: 0 | D6: 20 | E6: 45 | F6: 20 | G6: 0
A7: Carlos | B7: 10 | C7: 70 | D7: 0 | E7: 60 | F7: 40 | G7: 25
A8: Diana | B8: 0 | C8: 0 | D8: 0 | E8: 0 | F8: 0 | G8: 65
A9: Emma | B9: 0 | C9: 0 | D9: 0 | E9: 0 | F9: 0 | G9: 50
A10: Frank | B10: 0 | C10: 0 | D10: 0 | E10: 0 | F10: 0 | G10: 0
A12: A score of 0 below represents a forbidden pair, not an available zero-score match. Allowed-pair mask B26:G31 enforces the restrictions.
A14: Assign: mentor / mentee | B14: Alice | C14: Ben | D14: Carlos | E14: Diana | F14: Emma | G14: Frank | H14: Mentee load | I14: Capacity
A15: Alice | B15: 0 | C15: 0 | D15: 0 | E15: 1 | F15: 1 | G15: 1 | H15: =SUM(B15:G15) -> 3 | I15: 3
A16: Ben | B16: 1 | C16: 0 | D16: 1 | E16: 0 | F16: 0 | G16: 0 | H16: =SUM(B16:G16) -> 2 | I16: 3
A17: Carlos | B17: 0 | C17: 1 | D17: 0 | E17: 0 | F17: 0 | G17: 0 | H17: =SUM(B17:G17) -> 1 | I17: 3
A18: Diana | B18: 0 | C18: 0 | D18: 0 | E18: 0 | F18: 0 | G18: 0 | H18: =SUM(B18:G18) -> 0 | I18: 3
A19: Emma | B19: 0 | C19: 0 | D19: 0 | E19: 0 | F19: 0 | G19: 0 | H19: =SUM(B19:G19) -> 0 | I19: 3
A20: Frank | B20: 0 | C20: 0 | D20: 0 | E20: 0 | F20: 0 | G20: 0 | H20: =SUM(B20:G20) -> 0 | I20: 3
A22: Mentors assigned | B22: =SUM(B15:B20) -> 1 | C22: =SUM(C15:C20) -> 1 | D22: =SUM(D15:D20) -> 1 | E22: =SUM(E15:E20) -> 1 | F22: =SUM(F15:F20) -> 1 | G22: =SUM(G15:G20) -> 1
A23: Required | B23: 1 | C23: 1 | D23: 1 | E23: 1 | F23: 1 | G23: 1
A25: Allowed: mentor / mentee | B25: Alice | C25: Ben | D25: Carlos | E25: Diana | F25: Emma | G25: Frank
A26: Alice | B26: 0 | C26: 1 | D26: 1 | E26: 1 | F26: 1 | G26: 1
A27: Ben | B27: 1 | C27: 0 | D27: 1 | E27: 1 | F27: 1 | G27: 0
A28: Carlos | B28: 1 | C28: 1 | D28: 0 | E28: 1 | F28: 1 | G28: 1
A29: Diana | B29: 0 | C29: 0 | D29: 0 | E29: 0 | F29: 0 | G29: 1
A30: Emma | B30: 0 | C30: 0 | D30: 0 | E30: 0 | F30: 0 | G30: 1
A31: Frank | B31: 0 | C31: 0 | D31: 0 | E31: 0 | F31: 0 | G31: 0
A33: Total preference | B33: =SUMPRODUCT(B5:G10,B15:G20) -> 435
A35: Solver setting | B35: Specification
A36: Objective $B$33, Max; changing cells $B$15:$G$20; Simplex LP; non-negative variables.
A37: Constraints: $H$15:$H$20 <= $I$15:$I$20; $B$22:$G$22 = $B$23:$G$23; $B$15:$G$20 <= $B$26:$G$31.
A38: This network LP has an integral optimum. Binary constraints may alternatively be added to B15:G20; the optimum remains 435.
A40: Formula cell(s) | B40: Formula / explanation
A41: H15 (fill to H20) | B41: =SUM(B15:G15)
A42: B22 (fill across to G22) | B42: =SUM(B15:B20)
A43: B33 | B43: =SUMPRODUCT(B5:G10,B15:G20)
A45: Result: Alice mentors Diana, Emma, Frank; Ben mentors Alice and Carlos; Carlos mentors Ben. Total preference 435. The Ben-Carlos reciprocal assignment and Carlos's score 20 motivate fairness and cycle restrictions.
